INFO 2023-11-10 15:40:11,066 [root:accelerator.py:_autodetect_tpu_version:216]
Unable to poll TPU GCE metadata: HTTPConnectionPool(host='metadata.google.internal', port=80): Max retries exceeded with url: /computeMetadata/v1/instance/attributes/accelerator-type (Caused by NewConnectionError('<urllib3.connection.HTTPConnection object at 0x0000023415673070>: Failed to establish a new connection: [Errno 11001] getaddrinfo failed'))

INFO 2023-11-10 15:40:11,098 [root:accelerator.py:_autodetect_num_tpus:171]
Failed to detect number of TPUs: [WinError 3] The system cannot find the path specified: '/dev/vfio'

INFO 2023-11-13 14:09:19,565 [root:accelerator.py:_autodetect_tpu_version:216]
Unable to poll TPU GCE metadata: HTTPConnectionPool(host='metadata.google.internal', port=80): Max retries exceeded with url: /computeMetadata/v1/instance/attributes/accelerator-type (Caused by NewConnectionError('<urllib3.connection.HTTPConnection object at 0x000001660287AD00>: Failed to establish a new connection: [Errno 11001] getaddrinfo failed'))

INFO 2023-11-13 14:09:19,573 [root:accelerator.py:_autodetect_num_tpus:171]
Failed to detect number of TPUs: [WinError 3] The system cannot find the path specified: '/dev/vfio'

